Workbook

Sheet Patient Demographics
A1: Patient Id | B1: Patient Name | C1: Gender | D1: Date of Birth | E1: year | F1: dob | G1: age grp | H1: AGE GRP NO | I1: Income (LPA) | J1: Location (state) | K1: Region | L1: priority | M1: further tagging | O1: region unique | P1: count of region | Q1: count high priorit | R1: need attntion
A2: PID0001 | B2: Shreya Reddy | C2: Female | D2: 27029 | E2: =YEAR(D2) -> 1973 | F2: =DATEDIF(DATE(E2,1,1), TODAY(), "Y") -> 53 | G2: {=_xlfn.IFS(AND(F2>=21,F2<=35), "Young Adults", AND(F2>=35, F2<=45), "Senior Adullt", AND(F2>=46,F2<=65), "senior",AND(F2>=66,F2<=87),"Super Adults")} -> senior | I2: 20 | J2: Tamil Nadu | K2: South | L2: =IF(AND(I2<5,'Billing Details'!I2>10000),"High Priority","Regular Follow Up") -> Regular Follow Up | M2: =IF(AND(L2="High Priority",'Patient Health Records'!U2="Critical",'Patient Health Records'!T2="Yes"),"Needs Attention",IF(AND('Patient Health Records'!U2<> "Critical",'Patient Health Records'!T2="Yes"),"Monitor Later",IF(AND('Patient Health Records'!U2="Critical",'Patient Health Records'!T2="No"),"Ask for Readmission","No Action"))) -> Ask for Readmission | O2: South | P2: =COUNTIF(K2:K1001,O2) -> 363 | Q2: =COUNTIFS(K:K,O2,L:L,$L$6) -> 35 | R2: =COUNTIFS(K:K,O2,M:M,$M$28) -> 8
A3: PID0002 | B3: Isha Sharma | C3: Female | D3: 19724 | E3: =YEAR(D3) -> 1953 | F3: =DATEDIF(DATE(E3,1,1), TODAY(), "Y") -> 73 | G3: {=_xlfn.IFS(AND(F3>=21,F3<=35), "Young Adults", AND(F3>=35, F3<=45), "Senior Adullt", AND(F3>=46,F3<=65), "senior",AND(F3>=66,F3<=87),"Super Adults")} -> Super Adults | I3: 15 | J3: Maharashtra | K3: West | L3: =IF(AND(I3<5,'Billing Details'!I3>10000),"High Priority","Regular Follow Up") -> Regular Follow Up | M3: =IF(AND(L3="High Priority",'Patient Health Records'!U3="Critical",'Patient Health Records'!T3="Yes"),"Needs Attention",IF(AND('Patient Health Records'!U3<> "Critical",'Patient Health Records'!T3="Yes"),"Monitor Later",IF(AND('Patient Health Records'!U3="Critical",'Patient Health Records'!T3="No"),"Ask for Readmission","No Action"))) -> No Action | O3: West | P3: =COUNTIF(K2:K1001,O3) -> 249 | Q3: =COUNTIFS(K:K,O3,L:L,$L$6) -> 3 | R3: =COUNTIFS(K:K,O3,M:M,$M$28) -> 1
A4: PID0003 | B4: Isha Raj Reddy | C4: Female | D4: 34334 | E4: =YEAR(D4) -> 1993 | F4: =DATEDIF(DATE(E4,1,1), TODAY(), "Y") -> 33 | G4: {=_xlfn.IFS(AND(F4>=21,F4<=35), "Young Adults", AND(F4>=35, F4<=45), "Senior Adullt", AND(F4>=46,F4<=65), "senior",AND(F4>=66,F4<=87),"Super Adults")} -> Young Adults | I4: 20 | J4: Punjab | K4: North | L4: =IF(AND(I4<5,'Billing Details'!I4>10000),"High Priority","Regular Follow Up") -> Regular Follow Up | M4: =IF(AND(L4="High Priority",'Patient Health Records'!U4="Critical",'Patient Health Records'!T4="Yes"),"Needs Attention",IF(AND('Patient Health Records'!U4<> "Critical",'Patient Health Records'!T4="Yes"),"Monitor Later",IF(AND('Patient Health Records'!U4="Critical",'Patient Health Records'!T4="No"),"Ask for Readmission","No Action"))) -> Ask for Readmission | O4: North | P4: =COUNTIF(K3:K1002,O4) -> 252 | Q4: =COUNTIFS(K:K,O4,L:L,$L$6) -> 105 | R4: =COUNTIFS(K:K,O4,M:M,$M$28) -> 19
A5: PID0004 | B5: Aditya Patel | C5: Male | D5: 34334 | E5: =YEAR(D5) -> 1993 | F5: =DATEDIF(DATE(E5,1,1), TODAY(), "Y") -> 33 | G5: {=_xlfn.IFS(AND(F5>=21,F5<=35), "Young Adults", AND(F5>=35, F5<=45), "Senior Adullt", AND(F5>=46,F5<=65), "senior",AND(F5>=66,F5<=87),"Super Adults")} -> Young Adults | I5: 15 | J5: Karnataka | K5: South | L5: =IF(AND(I5<5,'Billing Details'!I5>10000),"High Priority","Regular Follow Up") -> Regular Follow Up | M5: =IF(AND(L5="High Priority",'Patient Health Records'!U5="Critical",'Patient Health Records'!T5="Yes"),"Needs Attention",IF(AND('Patient Health Records'!U5<> "Critical",'Patient Health Records'!T5="Yes"),"Monitor Later",IF(AND('Patient Health Records'!U5="Critical",'Patient Health Records'!T5="No"),"Ask for Readmission","No Action"))) -> Ask for Readmission | O5: East | P5: =COUNTIF(K4:K1003,O5) -> 136 | Q5: =COUNTIFS(K:K,O5,L:L,$L$6) -> 16 | R5: =COUNTIFS(K:K,O5,M:M,$M$28) -> 2
A6: PID0005 | B6: Aarav Mehta | C6: Male | D6: 32508 | E6: =YEAR(D6) -> 1988 | F6: =DATEDIF(DATE(E6,1,1), TODAY(), "Y") -> 38 | G6: {=_xlfn.IFS(AND(F6>=21,F6<=35), "Young Adults", AND(F6>=35, F6<=45), "Senior Adullt", AND(F6>=46,F6<=65), "senior",AND(F6>=66,F6<=87),"Super Adults")} -> Senior Adullt | I6: 2 | J6: Uttar Pradesh | K6: North | L6: =IF(AND(I6<5,'Billing Details'!I6>10000),"High Priority","Regular Follow Up") -> High Priority | M6: =IF(AND(L6="High Priority",'Patient Health Records'!U6="Critical",'Patient Health Records'!T6="Yes"),"Needs Attention",IF(AND('Patient Health Records'!U6<> "Critical",'Patient Health Records'!T6="Yes"),"Monitor Later",IF(AND('Patient Health Records'!U6="Critical",'Patient Health Records'!T6="No"),"Ask for Readmission","No Action"))) -> Needs Attention | P6: =SUM(P2:P5) -> 1000
A7: PID0006 | B7: Aarav Sharma | C7: Male | D7: 14245 | E7: =YEAR(D7) -> 1938 | F7: =DATEDIF(DATE(E7,1,1), TODAY(), "Y") -> 88 | G7: {=_xlfn.IFS(AND(F7>=21,F7<=35), "Young Adults", AND(F7>=35, F7<=45), "Senior Adullt", AND(F7>=46,F7<=65), "senior",AND(F7>=66,F7<=87),"Super Adults")} -> #N/A | I7: 20 | J7: Karnataka | K7: South | L7: =IF(AND(I7<5,'Billing Details'!I7>10000),"High Priority","Regular Follow Up") -> Regular Follow Up | M7: =IF(AND(L7="High Priority",'Patient Health Records'!U7="Critical",'Patient Health Records'!T7="Yes"),"Needs Attention",IF(AND('Patient Health Records'!U7<> "Critical",'Patient Health Records'!T7="Yes"),"Monitor Later",IF(AND('Patient Health Records'!U7="Critical",'Patient Health Records'!T7="No"),"Ask for Readmission","No Action"))) -> No Action
A8: PID0007 | B8: Sai Raj Patel | C8: Male | D8: 32508 | E8: =YEAR(D8) -> 1988 | F8: =DATEDIF(DATE(E8,1,1), TODAY(), "Y") -> 38 | G8: {=_xlfn.IFS(AND(F8>=21,F8<=35), "Young Adults", AND(F8>=35, F8<=45), "Senior Adullt", AND(F8>=46,F8<=65), "senior",AND(F8>=66,F8<=87),"Super Adults")} -> Senior Adullt | I8: 40 | J8: Maharashtra | K8: West | L8: =IF(AND(I8<5,'Billing Details'!I8>10000),"High Priority","Regular Follow Up") -> Regular Follow Up | M8: =IF(AND(L8="High Priority",'Patient Health Records'!U8="Critical",'Patient Health Records'!T8="Yes"),"Needs Attention",IF(AND('Patient Health Records'!U8<> "Critical",'Patient Health Records'!T8="Yes"),"Monitor Later",IF(AND('Patient Health Records'!U8="Critical",'Patient Health Records'!T8="No"),"Ask for Readmission","No Action"))) -> No Action
A9: PID0008 | B9: Shreya Reddy | C9: Female | D9: 34699 | E9: =YEAR(D9) -> 1994 | F9: =DATEDIF(DATE(E9,1,1), TODAY(), "Y") -> 32 | G9: {=_xlfn.IFS(AND(F9>=21,F9<=35), "Young Adults", AND(F9>=35, F9<=45), "Senior Adullt", AND(F9>=46,F9<=65), "senior",AND(F9>=66,F9<=87),"Super Adults")} -> Young Adults | I9: 30 | J9: Kerala | K9: South | L9: =IF(AND(I9<5,'Billing Details'!I9>10000),"High Priority","Regular Follow Up") -> Regular Follow Up | M9: =IF(AND(L9="High Priority",'Patient Health Records'!U9="Critical",'Patient Health Records'!T9="Yes"),"Needs Attention",IF(AND('Patient Health Records'!U9<> "Critical",'Patient Health Records'!T9="Yes"),"Monitor Later",IF(AND('Patient Health Records'!U9="Critical",'Patient Health Records'!T9="No"),"Ask for Readmission","No Action"))) -> Monitor Later
A10: PID0009 | B10: Diya Mehta | C10: Female | D10: 28855 | E10: =YEAR(D10) -> 1978 | F10: =DATEDIF(DATE(E10,1,1), TODAY(), "Y") -> 48 | G10: {=_xlfn.IFS(AND(F10>=21,F10<=35), "Young Adults", AND(F10>=35, F10<=45), "Senior Adullt", AND(F10>=46,F10<=65), "senior",AND(F10>=66,F10<=87),"Super Adults")} -> senior | I10: 20 | J10: Karnataka | K10: South | L10: =IF(AND(I10<5,'Billing Details'!I10>10000),"High Priority","Regular Follow Up") -> Regular Follow Up | M10: =IF(AND(L10="High Priority",'Patient Health Records'!U10="Critical",'Patient Health Records'!T10="Yes"),"Needs Attention",IF(AND('Patient Health Records'!U10<> "Critical",'Patient Health Records'!T10="Yes"),"Monitor Later",IF(AND('Patient Health Records'!U10="Critical",'Patient Health Records'!T10="No"),"Ask for Readmission","No Action"))) -> No Action
A11: PID0010 | B11: Vivaan Patel | C11: Male | D11: 34699 | E11: =YEAR(D11) -> 1994 | F11: =DATEDIF(DATE(E11,1,1), TODAY(), "Y") -> 32 | G11: {=_xlfn.IFS(AND(F11>=21,F11<=35), "Young Adults", AND(F11>=35, F11<=45), "Senior Adullt", AND(F11>=46,F11<=65), "senior",AND(F11>=66,F11<=87),"Super Adults")} -> Young Adults | I11: 2 | J11: West Bengal | K11: East | L11: =IF(AND(I11<5,'Billing Details'!I11>10000),"High Priority","Regular Follow Up") -> High Priority | M11: =IF(AND(L11="High Priority",'Patient Health Records'!U11="Critical",'Patient Health Records'!T11="Yes"),"Needs Attention",IF(AND('Patient Health Records'!U11<> "Critical",'Patient Health Records'!T11="Yes"),"Monitor Later",IF(AND('Patient Health Records'!U11="Critical",'Patient Health Records'!T11="No"),"Ask for Readmission","No Action"))) -> Ask for Readmission
A12: PID0011 | B12: Aditya Gupta | C12: Male | D12: 23377 | E12: =YEAR(D12) -> 1964 | F12: =DATEDIF(DATE(E12,1,1), TODAY(), "Y") -> 62 | G12: {=_xlfn.IFS(AND(F12>=21,F12<=35), "Young Adults", AND(F12>=35, F12<=45), "Senior Adullt", AND(F12>=46,F12<=65), "senior",AND(F12>=66,F12<=87),"Super Adults")} -> senior | I12: 3 | J12: Karnataka | K12: South | L12: =IF(AND(I12<5,'Billing Details'!I12>10000),"High Priority","Regular Follow Up") -> High Priority | M12: =IF(AND(L12="High Priority",'Patient Health Records'!U12="Critical",'Patient Health Records'!T12="Yes"),"Needs Attention",IF(AND('Patient Health Records'!U12<> "Critical",'Patient Health Records'!T12="Yes"),"Monitor Later",IF(AND('Patient Health Records'!U12="Critical",'Patient Health Records'!T12="No"),"Ask for Readmission","No Action"))) -> No Action
A13: PID0012 | B13: Aditya Sharma | C13: Male | D13: 23377 | E13: =YEAR(D13) -> 1964 | F13: =DATEDIF(DATE(E13,1,1), TODAY(), "Y") -> 62 | G13: {=_xlfn.IFS(AND(F13>=21,F13<=35), "Young Adults", AND(F13>=35, F13<=45), "Senior Adullt", AND(F13>=46,F13<=65), "senior",AND(F13>=66,F13<=87),"Super Adults")} -> senior | I13: 15 | J13: Tamil Nadu | K13: South | L13: =IF(AND(I13<5,'Billing Details'!I13>10000),"High Priority","Regular Follow Up") -> Regular Follow Up | M13: =IF(AND(L13="High Priority",'Patient Health Records'!U13="Critical",'Patient Health Records'!T13="Yes"),"Needs Attention",IF(AND('Patient Health Records'!U13<> "Critical",'Patient Health Records'!T13="Yes"),"Monitor Later",IF(AND('Patient Health Records'!U13="Critical",'Patient Health Records'!T13="No"),"Ask for Readmission","No Action"))) -> Monitor Later
A14: PID0013 | B14: Diya Kumar Sharma | C14: Female | D14: 27029 | E14: =YEAR(D14) -> 1973 | F14: =DATEDIF(DATE(E14,1,1), TODAY(), "Y") -> 53 | G14: {=_xlfn.IFS(AND(F14>=21,F14<=35), "Young Adults", AND(F14>=35, F14<=45), "Senior Adullt", AND(F14>=46,F14<=65), "senior",AND(F14>=66,F14<=87),"Super Adults")} -> senior | I14: 7 | J14: Kerala | K14: South | L14: =IF(AND(I14<5,'Billing Details'!I14>10000),"High Priority","Regular Follow Up") -> Regular Follow Up | M14: =IF(AND(L14="High Priority",'Patient Health Records'!U14="Critical",'Patient Health Records'!T14="Yes"),"Needs Attention",IF(AND('Patient Health Records'!U14<> "Critical",'Patient Health Records'!T14="Yes"),"Monitor Later",IF(AND('Patient Health Records'!U14="Critical",'Patient Health Records'!T14="No"),"Ask for Readmission","No Action"))) -> Monitor Later
A15: PID0014 | B15: Aanya Raj Sharma | C15: Female | D15: 29951 | E15: =YEAR(D15) -> 1981 | F15: =DATEDIF(DATE(E15,1,1), TODAY(), "Y") -> 45 | G15: {=_xlfn.IFS(AND(F15>=21,F15<=35), "Young Adults", AND(F15>=35, F15<=45), "Senior Adullt", AND(F15>=46,F15<=65), "senior",AND(F15>=66,F15<=87),"Super Adults")} -> Senior Adullt | I15: 15 | J15: Kerala | K15: South | L15: =IF(AND(I15<5,'Billing Details'!I15>10000),"High Priority","Regular Follow Up") -> Regular Follow Up | M15: =IF(AND(L15="High Priority",'Patient Health Records'!U15="Critical",'Patient Health Records'!T15="Yes"),"Needs Attention",IF(AND('Patient Health Records'!U15<> "Critical",'Patient Health Records'!T15="Yes"),"Monitor Later",IF(AND('Patient Health Records'!U15="Critical",'Patient Health Records'!T15="No"),"Ask for Readmission","No Action"))) -> No Action
A16: PID0015 | B16: Diya Priya Gupta | C16: Female | D16: 23377 | E16: =YEAR(D16) -> 1964 | F16: =DATEDIF(DATE(E16,1,1), TODAY(), "Y") -> 62 | G16: {=_xlfn.IFS(AND(F16>=21,F16<=35), "Young Adults", AND(F16>=35, F16<=45), "Senior Adullt", AND(F16>=46,F16<=65), "senior",AND(F16>=66,F16<=87),"Super Adults")} -> senior | I16: 2 | J16: Uttar Pradesh | K16: North | L16: =IF(AND(I16<5,'Billing Details'!I16>10000),"High Priority","Regular Follow Up") -> High Priority | M16: =IF(AND(L16="High Priority",'Patient Health Records'!U16="Critical",'Patient Health Records'!T16="Yes"),"Needs Attention",IF(AND('Patient Health Records'!U16<> "Critical",'Patient Health Records'!T16="Yes"),"Monitor Later",IF(AND('Patient Health Records'!U16="Critical",'Patient Health Records'!T16="No"),"Ask for Readmission","No Action"))) -> Ask for Readmission
A17: PID0016 | B17: Isha Kumar Mehta | C17: Female | D17: 34699 | E17: =YEAR(D17) -> 1994 | F17: =DATEDIF(DATE(E17,1,1), TODAY(), "Y") -> 32 | G17: {=_xlfn.IFS(AND(F17>=21,F17<=35), "Young Adults", AND(F17>=35, F17<=45), "Senior Adullt", AND(F17>=46,F17<=65), "senior",AND(F17>=66,F17<=87),"Super Adults")} -> Young Adults | I17: 15 | J17: Gujarat | K17: West | L17: =IF(AND(I17<5,'Billing Details'!I17>10000),"High Priority","Regular Follow Up") -> Regular Follow Up | M17: =IF(AND(L17="High Priority",'Patient Health Records'!U17="Critical",'Patient Health Records'!T17="Yes"),"Needs Attention",IF(AND('Patient Health Records'!U17<> "Critical",'Patient Health Records'!T17="Yes"),"Monitor Later",IF(AND('Patient Health Records'!U17="Critical",'Patient Health Records'!T17="No"),"Ask for Readmission","No Action"))) -> Monitor Later
A18: PID0017 | B18: Aditya Patel | C18: Male | D18: 30682 | E18: =YEAR(D18) -> 1984 | F18: =DATEDIF(DATE(E18,1,1), TODAY(), "Y") -> 42 | G18: {=_xlfn.IFS(AND(F18>=21,F18<=35), "Young Adults", AND(F18>=35, F18<=45), "Senior Adullt", AND(F18>=46,F18<=65), "senior",AND(F18>=66,F18<=87),"Super Adults")} -> Senior Adullt | I18: 7 | J18: Kerala | K18: South | L18: =IF(AND(I18<5,'Billing Details'!I18>10000),"High Priority","Regular Follow Up") -> Regular Follow Up | M18: =IF(AND(L18="High Priority",'Patient Health Records'!U18="Critical",'Patient Health Records'!T18="Yes"),"Needs Attention",IF(AND('Patient Health Records'!U18<> "Critical",'Patient Health Records'!T18="Yes"),"Monitor Later",IF(AND('Patient Health Records'!U18="Critical",'Patient Health Records'!T18="No"),"Ask for Readmission","No Action"))) -> No Action
... A27: PID0026 | B27: Aanya Priya Reddy | C27: Female | D27: 25203 | E27: =YEAR(D27) -> 1968 | F27: =DATEDIF(DATE(E27,1,1), TODAY(), "Y") -> 58 | G27: {=_xlfn.IFS(AND(F27>=21,F27<=35), "Young Adults", AND(F27>=35, F27<=45), "Senior Adullt", AND(F27>=46,F27<=65), "senior",AND(F27>=66,F27<=87),"Super Adults")} -> senior | I27: 2 | J27: Uttar Pradesh | K27: North | L27: =IF(AND(I27<5,'Billing Details'!I27>10000),"High Priority","Regular Follow Up") -> High Priority | M27: =IF(AND(L27="High Priority",'Patient Health Records'!U27="Critical",'Patient Health Records'!T27="Yes"),"Needs Attention",IF(AND('Patient Health Records'!U27<> "Critical",'Patient Health Records'!T27="Yes"),"Monitor Later",IF(AND('Patient Health Records'!U27="Critical",'Patient Health Records'!T27="No"),"Ask for Readmission","No Action"))) -> No Action
A28: PID0027 | B28: Riya Mehta | C28: Female | D28: 28855 | E28: =YEAR(D28) -> 1978 | F28: =DATEDIF(DATE(E28,1,1), TODAY(), "Y") -> 48 | G28: {=_xlfn.IFS(AND(F28>=21,F28<=35), "Young Adults", AND(F28>=35, F28<=45), "Senior Adullt", AND(F28>=46,F28<=65), "senior",AND(F28>=66,F28<=87),"Super Adults")} -> senior | J28: Gujarat | K28: West | L28: =IF(AND(I28<5,'Billing Details'!I28>10000),"High Priority","Regular Follow Up") -> High Priority | M28: =IF(AND(L28="High Priority",'Patient Health Records'!U28="Critical",'Patient Health Records'!T28="Yes"),"Needs Attention",IF(AND('Patient Health Records'!U28<> "Critical",'Patient Health Records'!T28="Yes"),"Monitor Later",IF(AND('Patient Health Records'!U28="Critical",'Patient Health Records'!T28="No"),"Ask for Readmission","No Action"))) -> Needs Attention
A29: PID0028 | B29: Aarav Sharma | C29: Male | D29: 34334 | E29: =YEAR(D29) -> 1993 | F29: =DATEDIF(DATE(E29,1,1), TODAY(), "Y") -> 33 | G29: {=_xlfn.IFS(AND(F29>=21,F29<=35), "Young Adults", AND(F29>=35, F29<=45), "Senior Adullt", AND(F29>=46,F29<=65), "senior",AND(F29>=66,F29<=87),"Super Adults")} -> Young Adults | I29: 25 | J29: Karnataka | K29: South | L29: =IF(AND(I29<5,'Billing Details'!I29>10000),"High Priority","Regular Follow Up") -> Regular Follow Up | M29: =IF(AND(L29="High Priority",'Patient Health Records'!U29="Critical",'Patient Health Records'!T29="Yes"),"Needs Attention",IF(AND('Patient Health Records'!U29<> "Critical",'Patient Health Records'!T29="Yes"),"Monitor Later",IF(AND('Patient Health Records'!U29="Critical",'Patient Health Records'!T29="No"),"Ask for Readmission","No Action"))) -> Monitor Later
A30: PID0029 | B30: Krishna Sharma | C30: Male | D30: 32508 | E30: =YEAR(D30) -> 1988 | F30: =DATEDIF(DATE(E30,1,1), TODAY(), "Y") -> 38 | G30: {=_xlfn.IFS(AND(F30>=21,F30<=35), "Young Adults", AND(F30>=35, F30<=45), "Senior Adullt", AND(F30>=46,F30<=65), "senior",AND(F30>=66,F30<=87),"Super Adults")} -> Senior Adullt | I30: 2 | J30: Uttar Pradesh | K30: North | L30: =IF(AND(I30<5,'Billing Details'!I30>10000),"High Priority","Regular Follow Up") -> High Priority | M30: =IF(AND(L30="High Priority",'Patient Health Records'!U30="Critical",'Patient Health Records'!T30="Yes"),"Needs Attention",IF(AND('Patient Health Records'!U30<> "Critical",'Patient Health Records'!T30="Yes"),"Monitor Later",IF(AND('Patient Health Records'!U30="Critical",'Patient Health Records'!T30="No"),"Ask for Readmission","No Action"))) -> Monitor Later
A31: PID0030 | B31: Aanya Priya Reddy | C31: Female | D31: 36160 | E31: =YEAR(D31) -> 1998 | F31: =DATEDIF(DATE(E31,1,1), TODAY(), "Y") -> 28 | G31: {=_xlfn.IFS(AND(F31>=21,F31<=35), "Young Adults", AND(F31>=35, F31<=45), "Senior Adullt", AND(F31>=46,F31<=65), "senior",AND(F31>=66,F31<=87),"Super Adults")} -> Young Adults | I31: 30 | J31: Uttar Pradesh | K31: North | L31: =IF(AND(I31<5,'Billing Details'!I31>10000),"High Priority","Regular Follow Up") -> Regular Follow Up | M31: =IF(AND(L31="High Priority",'Patient Health Records'!U31="Critical",'Patient Health Records'!T31="Yes"),"Needs Attention",IF(AND('Patient Health Records'!U31<> "Critical",'Patient Health Records'!T31="Yes"),"Monitor Later",IF(AND('Patient Health Records'!U31="Critical",'Patient Health Records'!T31="No"),"Ask for Readmission","No Action"))) -> No Action
A32: PID0031 | B32: Shreya Sharma | C32: Female | D32: 29951 | E32: =YEAR(D32) -> 1981 | F32: =DATEDIF(DATE(E32,1,1), TODAY(), "Y") -> 45 | G32: {=_xlfn.IFS(AND(F32>=21,F32<=35), "Young Adults", AND(F32>=35, F32<=45), "Senior Adullt", AND(F32>=46,F32<=65), "senior",AND(F32>=66,F32<=87),"Super Adults")} -> Senior Adullt | I32: 1 | J32: Uttar Pradesh | K32: North | L32: =IF(AND(I32<5,'Billing Details'!I32>10000),"High Priority","Regular Follow Up") -> High Priority | M32: =IF(AND(L32="High Priority",'Patient Health Records'!U32="Critical",'Patient Health Records'!T32="Yes"),"Needs Attention",IF(AND('Patient Health Records'!U32<> "Critical",'Patient Health Records'!T32="Yes"),"Monitor Later",IF(AND('Patient Health Records'!U32="Critical",'Patient Health Records'!T32="No"),"Ask for Readmission","No Action"))) -> Ask for Readmission
A33: PID0032 | B33: Isha Gupta | C33: Female | D33: 27029 | E33: =YEAR(D33) -> 1973 | F33: =DATEDIF(DATE(E33,1,1), TODAY(), "Y") -> 53 | G33: {=_xlfn.IFS(AND(F33>=21,F33<=35), "Young Adults", AND(F33>=35, F33<=45), "Senior Adullt", AND(F33>=46,F33<=65), "senior",AND(F33>=66,F33<=87),"Super Adults")} -> senior | I33: 9 | J33: Tamil Nadu | K33: South | L33: =IF(AND(I33<5,'Billing Details'!I33>10000),"High Priority","Regular Follow Up") -> Regular Follow Up | M33: =IF(AND(L33="High Priority",'Patient Health Records'!U33="Critical",'Patient Health Records'!T33="Yes"),"Needs Attention",IF(AND('Patient Health Records'!U33<> "Critical",'Patient Health Records'!T33="Yes"),"Monitor Later",IF(AND('Patient Health Records'!U33="Critical",'Patient Health Records'!T33="No"),"Ask for Readmission","No Action"))) -> No Action
A34: PID0033 | B34: Diya Sharma | C34: Female | D34: 36160 | E34: =YEAR(D34) -> 1998 | F34: =DATEDIF(DATE(E34,1,1), TODAY(), "Y") -> 28 | G34: {=_xlfn.IFS(AND(F34>=21,F34<=35), "Young Adults", AND(F34>=35, F34<=45), "Senior Adullt", AND(F34>=46,F34<=65), "senior",AND(F34>=66,F34<=87),"Super Adults")} -> Young Adults | I34: 15 | J34: Maharashtra | K34: West | L34: =IF(AND(I34<5,'Billing Details'!I34>10000),"High Priority","Regular Follow Up") -> Regular Follow Up | M34: =IF(AND(L34="High Priority",'Patient Health Records'!U34="Critical",'Patient Health Records'!T34="Yes"),"Needs Attention",IF(AND('Patient Health Records'!U34<> "Critical",'Patient Health Records'!T34="Yes"),"Monitor Later",IF(AND('Patient Health Records'!U34="Critical",'Patient Health Records'!T34="No"),"Ask for Readmission","No Action"))) -> Monitor Later
A35: PID0034 | B35: Aditya Mehta | C35: Male | D35: 30682 | E35: =YEAR(D35) -> 1984 | F35: =DATEDIF(DATE(E35,1,1), TODAY(), "Y") -> 42 | G35: {=_xlfn.IFS(AND(F35>=21,F35<=35), "Young Adults", AND(F35>=35, F35<=45), "Senior Adullt", AND(F35>=46,F35<=65), "senior",AND(F35>=66,F35<=87),"Super Adults")} -> Senior Adullt | I35: 15 | J35: Punjab | K35: North | L35: =IF(AND(I35<5,'Billing Details'!I35>10000),"High Priority","Regular Follow Up") -> Regular Follow Up | M35: =IF(AND(L35="High Priority",'Patient Health Records'!U35="Critical",'Patient Health Records'!T35="Yes"),"Needs Attention",IF(AND('Patient Health Records'!U35<> "Critical",'Patient Health Records'!T35="Yes"),"Monitor Later",IF(AND('Patient Health Records'!U35="Critical",'Patient Health Records'!T35="No"),"Ask for Readmission","No Action"))) -> No Action
A36: PID0035 | B36: Krishna Sharma | C36: Male | D36: 27760 | E36: =YEAR(D36) -> 1976 | F36: =DATEDIF(DATE(E36,1,1), TODAY(), "Y") -> 50 | G36: {=_xlfn.IFS(AND(F36>=21,F36<=35), "Young Adults", AND(F36>=35, F36<=45), "Senior Adullt", AND(F36>=46,F36<=65), "senior",AND(F36>=66,F36<=87),"Super Adults")} -> senior | I36: 2 | J36: Uttar Pradesh | K36: North | L36: =IF(AND(I36<5,'Billing Details'!I36>10000),"High Priority","Regular Follow Up") -> High Priority | M36: =IF(AND(L36="High Priority",'Patient Health Records'!U36="Critical",'Patient Health Records'!T36="Yes"),"Needs Attention",IF(AND('Patient Health Records'!U36<> "Critical",'Patient Health Records'!T36="Yes"),"Monitor Later",IF(AND('Patient Health Records'!U36="Critical",'Patient Health Records'!T36="No"),"Ask for Readmission","No Action"))) -> Needs Attention
A37: PID0036 | B37: Riya Gupta | C37: Female | D37: 25203 | E37: =YEAR(D37) -> 1968 | F37: =DATEDIF(DATE(E37,1,1), TODAY(), "Y") -> 58 | G37: {=_xlfn.IFS(AND(F37>=21,F37<=35), "Young Adults", AND(F37>=35, F37<=45), "Senior Adullt", AND(F37>=46,F37<=65), "senior",AND(F37>=66,F37<=87),"Super Adults")} -> senior | I37: 4 | J37: Punjab | K37: North | L37: =IF(AND(I37<5,'Billing Details'!I37>10000),"High Priority","Regular Follow Up") -> High Priority | M37: =IF(AND(L37="High Priority",'Patient Health Records'!U37="Critical",'Patient Health Records'!T37="Yes"),"Needs Attention",IF(AND('Patient Health Records'!U37<> "Critical",'Patient Health Records'!T37="Yes"),"Monitor Later",IF(AND('Patient Health Records'!U37="Critical",'Patient Health Records'!T37="No"),"Ask for Readmission","No Action"))) -> No Action
A38: PID0037 | B38: Aanya Priya Sharma | C38: Female | D38: 23377 | E38: =YEAR(D38) -> 1964 | F38: =DATEDIF(DATE(E38,1,1), TODAY(), "Y") -> 62 | G38: {=_xlfn.IFS(AND(F38>=21,F38<=35), "Young Adults", AND(F38>=35, F38<=45), "Senior Adullt", AND(F38>=46,F38<=65), "senior",AND(F38>=66,F38<=87),"Super Adults")} -> senior | I38: 5 | J38: Gujarat | K38: West | L38: =IF(AND(I38<5,'Billing Details'!I38>10000),"High Priority","Regular Follow Up") -> Regular Follow Up | M38: =IF(AND(L38="High Priority",'Patient Health Records'!U38="Critical",'Patient Health Records'!T38="Yes"),"Needs Attention",IF(AND('Patient Health Records'!U38<> "Critical",'Patient Health Records'!T38="Yes"),"Monitor Later",IF(AND('Patient Health Records'!U38="Critical",'Patient Health Records'!T38="No"),"Ask for Readmission","No Action"))) -> No Action
A39: PID0038 | B39: Sai Priya Mehta | C39: Male | D39: 32508 | E39: =YEAR(D39) -> 1988 | F39: =DATEDIF(DATE(E39,1,1), TODAY(), "Y") -> 38 | G39: {=_xlfn.IFS(AND(F39>=21,F39<=35), "Young Adults", AND(F39>=35, F39<=45), "Senior Adullt", AND(F39>=46,F39<=65), "senior",AND(F39>=66,F39<=87),"Super Adults")} -> Senior Adullt | I39: 15 | J39: Karnataka | K39: South | L39: =IF(AND(I39<5,'Billing Details'!I39>10000),"High Priority","Regular Follow Up") -> Regular Follow Up | M39: =IF(AND(L39="High Priority",'Patient Health Records'!U39="Critical",'Patient Health Records'!T39="Yes"),"Needs Attention",IF(AND('Patient Health Records'!U39<> "Critical",'Patient Health Records'!T39="Yes"),"Monitor Later",IF(AND('Patient Health Records'!U39="Critical",'Patient Health Records'!T39="No"),"Ask for Readmission","No Action"))) -> No Action
A40: PID0039 | B40: Isha Kumar Sharma | C40: Female | D40: 27029 | E40: =YEAR(D40) -> 1973 | F40: =DATEDIF(DATE(E40,1,1), TODAY(), "Y") -> 53 | G40: {=_xlfn.IFS(AND(F40>=21,F40<=35), "Young Adults", AND(F40>=35, F40<=45), "Senior Adullt", AND(F40>=46,F40<=65), "senior",AND(F40>=66,F40<=87),"Super Adults")} -> senior | I40: 25 | J40: Gujarat | K40: West | L40: =IF(AND(I40<5,'Billing Details'!I40>10000),"High Priority","Regular Follow Up") -> Regular Follow Up | M40: =IF(AND(L40="High Priority",'Patient Health Records'!U40="Critical",'Patient Health Records'!T40="Yes"),"Needs Attention",IF(AND('Patient Health Records'!U40<> "Critical",'Patient Health Records'!T40="Yes"),"Monitor Later",IF(AND('Patient Health Records'!U40="Critical",'Patient Health Records'!T40="No"),"Ask for Readmission","No Action"))) -> No Action
... A54: PID0053 | B54: Isha Sharma | C54: Female | D54: 23377 | E54: =YEAR(D54) -> 1964 | F54: =DATEDIF(DATE(E54,1,1), TODAY(), "Y") -> 62 | G54: {=_xlfn.IFS(AND(F54>=21,F54<=35), "Young Adults", AND(F54>=35, F54<=45), "Senior Adullt", AND(F54>=46,F54<=65), "senior",AND(F54>=66,F54<=87),"Super Adults")} -> senior | I54: 300 | J54: Gujarat | K54: West | L54: =IF(AND(I54<5,'Billing Details'!I54>10000),"High Priority","Regular Follow Up") -> Regular Follow Up | M54: =IF(AND(L54="High Priority",'Patient Health Records'!U54="Critical",'Patient Health Records'!T54="Yes"),"Needs Attention",IF(AND('Patient Health Records'!U54<> "Critical",'Patient Health Records'!T54="Yes"),"Monitor Later",IF(AND('Patient Health Records'!U54="Critical",'Patient Health Records'!T54="No"),"Ask for Readmission","No Action"))) -> No Action
A55: PID0054 | B55: Aarav Patel | C55: Male | D55: 30682 | E55: =YEAR(D55) -> 1984 | F55: =DATEDIF(DATE(E55,1,1), TODAY(), "Y") -> 42 | G55: {=_xlfn.IFS(AND(F55>=21,F55<=35), "Young Adults", AND(F55>=35, F55<=45), "Senior Adullt", AND(F55>=46,F55<=65), "senior",AND(F55>=66,F55<=87),"Super Adults")} -> Senior Adullt | J55: Gujarat | K55: West | L55: =IF(AND(I55<5,'Billing Details'!I55>10000),"High Priority","Regular Follow Up") -> Regular Follow Up | M55: =IF(AND(L55="High Priority",'Patient Health Records'!U55="Critical",'Patient Health Records'!T55="Yes"),"Needs Attention",IF(AND('Patient Health Records'!U55<> "Critical",'Patient Health Records'!T55="Yes"),"Monitor Later",IF(AND('Patient Health Records'!U55="Critical",'Patient Health Records'!T55="No"),"Ask for Readmission","No Action"))) -> Monitor Later
A56: PID0055 | B56: Isha Patel | C56: Female | D56: 28855 | E56: =YEAR(D56) -> 1978 | F56: =DATEDIF(DATE(E56,1,1), TODAY(), "Y") -> 48 | G56: {=_xlfn.IFS(AND(F56>=21,F56<=35), "Young Adults", AND(F56>=35, F56<=45), "Senior Adullt", AND(F56>=46,F56<=65), "senior",AND(F56>=66,F56<=87),"Super Adults")} -> senior | I56: 4 | J56: Punjab | K56: North | L56: =IF(AND(I56<5,'Billing Details'!I56>10000),"High Priority","Regular Follow Up") -> High Priority | M56: =IF(AND(L56="High Priority",'Patient Health Records'!U56="Critical",'Patient Health Records'!T56="Yes"),"Needs Attention",IF(AND('Patient Health Records'!U56<> "Critical",'Patient Health Records'!T56="Yes"),"Monitor Later",IF(AND('Patient Health Records'!U56="Critical",'Patient Health Records'!T56="No"),"Ask for Readmission","No Action"))) -> Monitor Later
A57: PID0056 | B57: Isha Kumar Reddy | C57: Female | D57: 23377 | E57: =YEAR(D57) -> 1964 | F57: =DATEDIF(DATE(E57,1,1), TODAY(), "Y") -> 62 | G57: {=_xlfn.IFS(AND(F57>=21,F57<=35), "Young Adults", AND(F57>=35, F57<=45), "Senior Adullt", AND(F57>=46,F57<=65), "senior",AND(F57>=66,F57<=87),"Super Adults")} -> senior | I57: 2 | J57: Uttar Pradesh | K57: North | L57: =IF(AND(I57<5,'Billing Details'!I57>10000),"High Priority","Regular Follow Up") -> High Priority | M57: =IF(AND(L57="High Priority",'Patient Health Records'!U57="Critical",'Patient Health Records'!T57="Yes"),"Needs Attention",IF(AND('Patient Health Records'!U57<> "Critical",'Patient Health Records'!T57="Yes"),"Monitor Later",IF(AND('Patient Health Records'!U57="Critical",'Patient Health Records'!T57="No"),"Ask for Readmission","No Action"))) -> No Action
A58: PID0057 | B58: Aarav Reddy | C58: Male | D58: 26299 | E58: =YEAR(D58) -> 1972 | F58: =DATEDIF(DATE(E58,1,1), TODAY(), "Y") -> 54 | G58: {=_xlfn.IFS(AND(F58>=21,F58<=35), "Young Adults", AND(F58>=35, F58<=45), "Senior Adullt", AND(F58>=46,F58<=65), "senior",AND(F58>=66,F58<=87),"Super Adults")} -> senior | I58: 2 | J58: Punjab | K58: North | L58: =IF(AND(I58<5,'Billing Details'!I58>10000),"High Priority","Regular Follow Up") -> Regular Follow Up | M58: =IF(AND(L58="High Priority",'Patient Health Records'!U58="Critical",'Patient Health Records'!T58="Yes"),"Needs Attention",IF(AND('Patient Health Records'!U58<> "Critical",'Patient Health Records'!T58="Yes"),"Monitor Later",IF(AND('Patient Health Records'!U58="Critical",'Patient Health Records'!T58="No"),"Ask for Readmission","No Action"))) -> Monitor Later
A59: PID0058 | B59: Aditya Dev Sharma | C59: Male | D59: 31412 | E59: =YEAR(D59) -> 1985 | F59: =DATEDIF(DATE(E59,1,1), TODAY(), "Y") -> 41 | G59: {=_xlfn.IFS(AND(F59>=21,F59<=35), "Young Adults", AND(F59>=35, F59<=45), "Senior Adullt", AND(F59>=46,F59<=65), "senior",AND(F59>=66,F59<=87),"Super Adults")} -> Senior Adullt | I59: 5 | J59: Kerala | K59: South | L59: =IF(AND(I59<5,'Billing Details'!I59>10000),"High Priority","Regular Follow Up") -> Regular Follow Up | M59: =IF(AND(L59="High Priority",'Patient Health Records'!U59="Critical",'Patient Health Records'!T59="Yes"),"Needs Attention",IF(AND('Patient Health Records'!U59<> "Critical",'Patient Health Records'!T59="Yes"),"Monitor Later",IF(AND('Patient Health Records'!U59="Critical",'Patient Health Records'!T59="No"),"Ask for Readmission","No Action"))) -> Monitor Later
A60: PID0059 | B60: Isha Patel | C60: Female | D60: 28855 | E60: =YEAR(D60) -> 1978 | F60: =DATEDIF(DATE(E60,1,1), TODAY(), "Y") -> 48 | G60: {=_xlfn.IFS(AND(F60>=21,F60<=35), "Young Adults", AND(F60>=35, F60<=45), "Senior Adullt", AND(F60>=46,F60<=65), "senior",AND(F60>=66,F60<=87),"Super Adults")} -> senior | I60: 20 | J60: Kerala | K60: South | L60: =IF(AND(I60<5,'Billing Details'!I60>10000),"High Priority","Regular Follow Up") -> Regular Follow Up | M60: =IF(AND(L60="High Priority",'Patient Health Records'!U60="Critical",'Patient Health Records'!T60="Yes"),"Needs Attention",IF(AND('Patient Health Records'!U60<> "Critical",'Patient Health Records'!T60="Yes"),"Monitor Later",IF(AND('Patient Health Records'!U60="Critical",'Patient Health Records'!T60="No"),"Ask for Readmission","No Action"))) -> No Action
A61: PID0060 | B61: Vivaan Reddy | C61: Male | D61: 30682 | E61: =YEAR(D61) -> 1984 | F61: =DATEDIF(DATE(E61,1,1), TODAY(), "Y") -> 42 | G61: {=_xlfn.IFS(AND(F61>=21,F61<=35), "Young Adults", AND(F61>=35, F61<=45), "Senior Adullt", AND(F61>=46,F61<=65), "senior",AND(F61>=66,F61<=87),"Super Adults")} -> Senior Adullt | I61: 1 | J61: Uttar Pradesh | K61: North | L61: =IF(AND(I61<5,'Billing Details'!I61>10000),"High Priority","Regular Follow Up") -> Regular Follow Up | M61: =IF(AND(L61="High Priority",'Patient Health Records'!U61="Critical",'Patient Health Records'!T61="Yes"),"Needs Attention",IF(AND('Patient Health Records'!U61<> "Critical",'Patient Health Records'!T61="Yes"),"Monitor Later",IF(AND('Patient Health Records'!U61="Critical",'Patient Health Records'!T61="No"),"Ask for Readmission","No Action"))) -> Monitor Later
...

Sheet Sheet2
A1: 1
A2: 2
A3: 3
A4: 4
A5: 5
A6: 6
A7: 7
A8: 8
A9: 9
A10: 10
A11: 11
A12: 12
... A5532: 5532

Sheet Sheet1
A1: Function,Description,Example
A2: SUM,Adds all numbers in a given range.,=SUM(A1:A5)
A3: COUNT,Counts the number of numeric values in a range.,=COUNT(A1:A5)
A4: SUMIF,Sums values based on a single condition.,"=SUMIF(A1:A5, "">10"")"
A5: COUNTIF,Counts cells based on a single condition.,"=COUNTIF(A1:A5, "">10"")"
A6: SUMIFS,Sums values based on multiple conditions.,"=SUMIFS(A1:A5, B1:B5, "">10"", C1:C5, ""South"")"
A7: COUNTIFS,Counts cells based on multiple conditions.,"=COUNTIFS(A1:A5, "">10"", B1:B5, ""South"")"
A8: IF,"Returns one value if a condition is true, and another if false.","=IF(A1>10, ""Yes"", ""No"")"
A9: AND,Returns TRUE if all conditions are true.,"=AND(A1>10, B1<5)"
A10: OR,Returns TRUE if at least one condition is true.,"=OR(A1>10, B1<5)"

Sheet Patient Health Records
A1: Patient Id | B1: Blood Type | C1: Height (cm) | D1: height (m) | E1: Weight (kg) | F1: bmi | G1: Fever | H1: Cough | I1: Fatigue | J1: Difficulty Breathing | K1: Blood Pressure | L1: Cholesterol Level | M1: Smoking Status | N1: updated smoking status | O1: Drinking Status | P1: updated drinking status | Q1: Diabetes | R1: updated Diabetic | S1: Condition | T1: Readmission | U1: Outcome | V1: Satisfaction
A2: PID0001 | B2: O+ | C2: 168 | D2: =C2/100 -> 1.68 | E2: 82.4 | F2: =E2/(D2*D2) -> 29.195011 | G2: FALSE | H2: FALSE | I2: FALSE | J2: FALSE | K2: 129/83 | L2: 151 | M2: FALSE | N2: =IF(ISBLANK(M2),FALSE,IF(M2 ="Yes",TRUE,IF(M2="No",FALSE,M2))) -> FALSE | O2: TRUE | P2: =IF(ISBLANK(O2),FALSE,IF(O2 ="Yes",TRUE,IF(O2="No",FALSE,O2))) -> TRUE | Q2: TRUE | R2: =IF(ISBLANK(Q2),FALSE,IF(Q2 ="Yes",TRUE,IF(Q2="No",FALSE,Q2))) -> TRUE | S2: Fractured Leg | T2: No | U2: Critical | V2: Dissatisfied | X2: {=_xlfn.UNIQUE(S2:S1001)} -> Fractured Leg | Y2: =COUNTIF(S2:S1001,X2) -> 69 | Z2: =_xlfn.MODE.SNGL(Y2:Y16) -> 69 | AA2: =MEDIAN(Y2:Y16) -> 69 | AB2: =AVERAGE(Y2:Y16) -> 66.666667
A3: PID0002 | B3: AB- | C3: 152 | D3: =C3/100 -> 1.52 | E3: 64.8 | F3: =E3/(D3*D3) -> 28.047091 | G3: FALSE | H3: FALSE | I3: FALSE | J3: FALSE | K3: 112/81 | L3: 191 | M3: FALSE | N3: =IF(ISBLANK(M3),FALSE,IF(M3 ="Yes",TRUE,IF(M3="No",FALSE,M3))) -> FALSE | O3: TRUE | P3: =IF(ISBLANK(O3),FALSE,IF(O3 ="Yes",TRUE,IF(O3="No",FALSE,O3))) -> TRUE | Q3: TRUE | R3: =IF(ISBLANK(Q3),FALSE,IF(Q3 ="Yes",TRUE,IF(Q3="No",FALSE,Q3))) -> TRUE | S3: Prostate Cancer | T3: No | U3: Recovered | V3: Very Dissatisfied | X3: Prostate Cancer | Y3: =COUNTIF(S3:S1002,X3) -> 74
A4: PID0003 | B4: B+ | C4: 170 | D4: =C4/100 -> 1.7 | E4: 69.4 | F4: =E4/(D4*D4) -> 24.013841 | G4: TRUE | H4: FALSE | I4: FALSE | J4: FALSE | K4: 125/74 | L4: 152 | M4: FALSE | N4: =IF(ISBLANK(M4),FALSE,IF(M4 ="Yes",TRUE,IF(M4="No",FALSE,M4))) -> FALSE | P4: =IF(ISBLANK(O4),FALSE,IF(O4 ="Yes",TRUE,IF(O4="No",FALSE,O4))) -> FALSE | Q4: FALSE | R4: =IF(ISBLANK(Q4),FALSE,IF(Q4 ="Yes",TRUE,IF(Q4="No",FALSE,Q4))) -> FALSE | S4: Stroke | T4: No | U4: Critical | V4: Very Satisfied | X4: Stroke | Y4: =COUNTIF(S4:S1003,X4) -> 62
A5: PID0004 | B5: A- | C5: 169 | D5: =C5/100 -> 1.69 | E5: 89.3 | F5: =E5/(D5*D5) -> 31.266412 | G5: TRUE | H5: TRUE | I5: FALSE | J5: FALSE | K5: 122/72 | L5: 203 | M5: TRUE | N5: =IF(ISBLANK(M5),FALSE,IF(M5 ="Yes",TRUE,IF(M5="No",FALSE,M5))) -> TRUE | O5: FALSE | P5: =IF(ISBLANK(O5),FALSE,IF(O5 ="Yes",TRUE,IF(O5="No",FALSE,O5))) -> FALSE | Q5: TRUE | R5: =IF(ISBLANK(Q5),FALSE,IF(Q5 ="Yes",TRUE,IF(Q5="No",FALSE,Q5))) -> TRUE | S5: Heart Attack | T5: No | U5: Critical | V5: Neutral | X5: Heart Attack | Y5: =COUNTIF(S5:S1004,X5) -> 71
A6: PID0005 | B6: O+ | C6: 161 | D6: =C6/100 -> 1.61 | E6: 69.4 | F6: =E6/(D6*D6) -> 26.773658 | G6: TRUE | H6: FALSE | I6: TRUE | J6: FALSE | K6: 110/80 | L6: 164 | M6: FALSE | N6: =IF(ISBLANK(M6),FALSE,IF(M6 ="Yes",TRUE,IF(M6="No",FALSE,M6))) -> FALSE | O6: FALSE | P6: =IF(ISBLANK(O6),FALSE,IF(O6 ="Yes",TRUE,IF(O6="No",FALSE,O6))) -> FALSE | R6: =IF(ISBLANK(Q6),FALSE,IF(Q6 ="Yes",TRUE,IF(Q6="No",FALSE,Q6))) -> FALSE | S6: Appendicitis | T6: Yes | U6: Critical | V6: Dissatisfied | X6: Appendicitis | Y6: =COUNTIF(S6:S1005,X6) -> 65
A7: PID0006 | B7: O+ | C7: 157 | D7: =C7/100 -> 1.57 | E7: 76.6 | F7: =E7/(D7*D7) -> 31.076311 | G7: TRUE | H7: FALSE | I7: FALSE | J7: FALSE | K7: 110/73 | L7: 223 | M7: FALSE | N7: =IF(ISBLANK(M7),FALSE,IF(M7 ="Yes",TRUE,IF(M7="No",FALSE,M7))) -> FALSE | O7: TRUE | P7: =IF(ISBLANK(O7),FALSE,IF(O7 ="Yes",TRUE,IF(O7="No",FALSE,O7))) -> TRUE | Q7: TRUE | R7: =IF(ISBLANK(Q7),FALSE,IF(Q7 ="Yes",TRUE,IF(Q7="No",FALSE,Q7))) -> TRUE | S7: Fractured Arm | T7: Yes | U7: Critical | V7: Very Dissatisfied | X7: Fractured Arm | Y7: =COUNTIF(S7:S1006,X7) -> 60
A8: PID0007 | B8: O- | C8: 172 | D8: =C8/100 -> 1.72 | E8: 91.5 | F8: =E8/(D8*D8) -> 30.92888 | G8: FALSE | H8: FALSE | I8: TRUE | J8: FALSE | K8: 123/75 | L8: 219 | M8: FALSE | N8: =IF(ISBLANK(M8),FALSE,IF(M8 ="Yes",TRUE,IF(M8="No",FALSE,M8))) -> FALSE | O8: TRUE | P8: =IF(ISBLANK(O8),FALSE,IF(O8 ="Yes",TRUE,IF(O8="No",FALSE,O8))) -> TRUE | Q8: TRUE | R8: =IF(ISBLANK(Q8),FALSE,IF(Q8 ="Yes",TRUE,IF(Q8="No",FALSE,Q8))) -> TRUE | S8: Childbirth | T8: No | U8: Recovered | V8: Satisfied | X8: Childbirth | Y8: =COUNTIF(S8:S1007,X8) -> 66
A9: PID0008 | B9: O- | C9: 161 | D9: =C9/100 -> 1.61 | E9: 75.6 | F9: =E9/(D9*D9) -> 29.165541 | G9: TRUE | H9: FALSE | I9: TRUE | J9: TRUE | K9: 114/70 | L9: 211 | M9: TRUE | N9: =IF(ISBLANK(M9),FALSE,IF(M9 ="Yes",TRUE,IF(M9="No",FALSE,M9))) -> TRUE | O9: FALSE | P9: =IF(ISBLANK(O9),FALSE,IF(O9 ="Yes",TRUE,IF(O9="No",FALSE,O9))) -> FALSE | Q9: TRUE | R9: =IF(ISBLANK(Q9),FALSE,IF(Q9 ="Yes",TRUE,IF(Q9="No",FALSE,Q9))) -> TRUE | S9: Hypertension | T9: Yes | U9: Recovered | V9: Dissatisfied | X9: Hypertension | Y9: =COUNTIF(S9:S1008,X9) -> 69
A10: PID0009 | B10: AB- | C10: 176 | D10: =C10/100 -> 1.76 | E10: 90.7 | F10: =E10/(D10*D10) -> 29.280733 | G10: FALSE | H10: FALSE | I10: FALSE | J10: TRUE | K10: 124/84 | L10: 201 | M10: TRUE | N10: =IF(ISBLANK(M10),FALSE,IF(M10 ="Yes",TRUE,IF(M10="No",FALSE,M10))) -> TRUE | O10: TRUE | P10: =IF(ISBLANK(O10),FALSE,IF(O10 ="Yes",TRUE,IF(O10="No",FALSE,O10))) -> TRUE | Q10: TRUE | R10: =IF(ISBLANK(Q10),FALSE,IF(Q10 ="Yes",TRUE,IF(Q10="No",FALSE,Q10))) -> TRUE | S10: Respiratory Infection | T10: No | U10: Ongoing Treatment | V10: Dissatisfied | X10: Respiratory Infection | Y10: =COUNTIF(S10:S1009,X10) -> 64
A11: PID0010 | B11: A+ | C11: 171 | D11: =C11/100 -> 1.71 | E11: 97.9 | F11: =E11/(D11*D11) -> 33.480387 | G11: TRUE | H11: FALSE | I11: TRUE | J11: FALSE | K11: 116/80 | L11: 224 | M11: Yes | N11: =IF(ISBLANK(M11),FALSE,IF(M11 ="Yes",TRUE,IF(M11="No",FALSE,M11))) -> TRUE | P11: =IF(ISBLANK(O11),FALSE,IF(O11 ="Yes",TRUE,IF(O11="No",FALSE,O11))) -> FALSE | Q11: TRUE | R11: =IF(ISBLANK(Q11),FALSE,IF(Q11 ="Yes",TRUE,IF(Q11="No",FALSE,Q11))) -> TRUE | S11: Heart Attack | T11: No | U11: Critical | V11: Very Dissatisfied | X11: Osteoarthritis | Y11: =COUNTIF(S11:S1010,X11) -> 51
A12: PID0011 | B12: AB- | C12: 167 | D12: =C12/100 -> 1.67 | E12: 83.9 | F12: =E12/(D12*D12) -> 30.083545 | G12: FALSE | H12: FALSE | I12: FALSE | J12: FALSE | K12: 129/71 | L12: 192 | M12: FALSE | N12: =IF(ISBLANK(M12),FALSE,IF(M12 ="Yes",TRUE,IF(M12="No",FALSE,M12))) -> FALSE | O12: TRUE | P12: =IF(ISBLANK(O12),FALSE,IF(O12 ="Yes",TRUE,IF(O12="No",FALSE,O12))) -> TRUE | Q12: TRUE | R12: =IF(ISBLANK(Q12),FALSE,IF(Q12 ="Yes",TRUE,IF(Q12="No",FALSE,Q12))) -> TRUE | S12: Appendicitis | T12: No | U12: Ongoing Treatment | V12: Very Satisfied | X12: Kidney Stones | Y12: =COUNTIF(S12:S1011,X12) -> 73
A13: PID0012 | B13: A+ | C13: 159 | D13: =C13/100 -> 1.59 | E13: 78.7 | F13: =E13/(D13*D13) -> 31.130098 | G13: FALSE | H13: TRUE | I13: TRUE | J13: TRUE | K13: 110/70 | L13: 215 | M13: TRUE | N13: =IF(ISBLANK(M13),FALSE,IF(M13 ="Yes",TRUE,IF(M13="No",FALSE,M13))) -> TRUE | O13: FALSE | P13: =IF(ISBLANK(O13),FALSE,IF(O13 ="Yes",TRUE,IF(O13="No",FALSE,O13))) -> FALSE | Q13: TRUE | R13: =IF(ISBLANK(Q13),FALSE,IF(Q13 ="Yes",TRUE,IF(Q13="No",FALSE,Q13))) -> TRUE | S13: Osteoarthritis | T13: Yes | U13: Recovered | V13: Very Satisfied | X13: Heart Disease | Y13: =COUNTIF(S13:S1012,X13) -> 71
A14: PID0013 | B14: O+ | C14: 166 | D14: =C14/100 -> 1.66 | E14: 92.9 | F14: =E14/(D14*D14) -> 33.713166 | G14: TRUE | H14: TRUE | I14: FALSE | J14: TRUE | K14: 126/76 | L14: 188 | M14: TRUE | N14: =IF(ISBLANK(M14),FALSE,IF(M14 ="Yes",TRUE,IF(M14="No",FALSE,M14))) -> TRUE | O14: TRUE | P14: =IF(ISBLANK(O14),FALSE,IF(O14 ="Yes",TRUE,IF(O14="No",FALSE,O14))) -> TRUE | Q14: TRUE | R14: =IF(ISBLANK(Q14),FALSE,IF(Q14 ="Yes",TRUE,IF(Q14="No",FALSE,Q14))) -> TRUE | S14: Kidney Stones | T14: Yes | U14: Ongoing Treatment | V14: Very Satisfied | X14: Allergic Reaction | Y14: =COUNTIF(S14:S1013,X14) -> 54
A15: PID0014 | B15: AB+ | C15: 171 | D15: =C15/100 -> 1.71 | E15: 78.3 | F15: =E15/(D15*D15) -> 26.77747 | G15: FALSE | H15: FALSE | I15: FALSE | J15: FALSE | K15: 116/89 | L15: 190 | M15: FALSE | N15: =IF(ISBLANK(M15),FALSE,IF(M15 ="Yes",TRUE,IF(M15="No",FALSE,M15))) -> FALSE | O15: FALSE | P15: =IF(ISBLANK(O15),FALSE,IF(O15 ="Yes",TRUE,IF(O15="No",FALSE,O15))) -> FALSE | Q15: FALSE | R15: =IF(ISBLANK(Q15),FALSE,IF(Q15 ="Yes",TRUE,IF(Q15="No",FALSE,Q15))) -> FALSE | S15: Hypertension | T15: Yes | U15: Critical | V15: Very Satisfied | X15: Diabetes | Y15: =COUNTIF(S15:S1014,X15) -> 81
A16: PID0015 | B16: AB+ | C16: 157 | D16: =C16/100 -> 1.57 | E16: 60.1 | F16: =E16/(D16*D16) -> 24.382328 | G16: TRUE | H16: TRUE | I16: FALSE | J16: FALSE | K16: 129/73 | L16: 221 | M16: FALSE | N16: =IF(ISBLANK(M16),FALSE,IF(M16 ="Yes",TRUE,IF(M16="No",FALSE,M16))) -> FALSE | O16: No | P16: =IF(ISBLANK(O16),FALSE,IF(O16 ="Yes",TRUE,IF(O16="No",FALSE,O16))) -> FALSE | Q16: FALSE | R16: =IF(ISBLANK(Q16),FALSE,IF(Q16 ="Yes",TRUE,IF(Q16="No",FALSE,Q16))) -> FALSE | S16: Stroke | T16: No | U16: Critical | V16: Very Dissatisfied | X16: Cancer | Y16: =COUNTIF(S16:S1015,X16) -> 70
A17: PID0016 | B17: B+ | C17: 165 | D17: =C17/100 -> 1.65 | E17: 91.6 | F17: =E17/(D17*D17) -> 33.645546 | G17: TRUE | H17: FALSE | I17: FALSE | J17: FALSE | K17: 112/86 | L17: 186 | M17: TRUE | N17: =IF(ISBLANK(M17),FALSE,IF(M17 ="Yes",TRUE,IF(M17="No",FALSE,M17))) -> TRUE | O17: FALSE | P17: =IF(ISBLANK(O17),FALSE,IF(O17 ="Yes",TRUE,IF(O17="No",FALSE,O17))) -> FALSE | Q17: TRUE | R17: =IF(ISBLANK(Q17),FALSE,IF(Q17 ="Yes",TRUE,IF(Q17="No",FALSE,Q17))) -> TRUE | S17: Heart Disease | T17: Yes | U17: Ongoing Treatment | V17: Dissatisfied
A18: PID0017 | B18: A+ | C18: 167 | D18: =C18/100 -> 1.67 | E18: 60.6 | F18: =E18/(D18*D18) -> 21.728997 | G18: FALSE | H18: FALSE | I18: TRUE | J18: FALSE | K18: 129/85 | L18: 170 | M18: FALSE | N18: =IF(ISBLANK(M18),FALSE,IF(M18 ="Yes",TRUE,IF(M18="No",FALSE,M18))) -> FALSE | O18: FALSE | P18: =IF(ISBLANK(O18),FALSE,IF(O18 ="Yes",TRUE,IF(O18="No",FALSE,O18))) -> FALSE | Q18: FALSE | R18: =IF(ISBLANK(Q18),FALSE,IF(Q18 ="Yes",TRUE,IF(Q18="No",FALSE,Q18))) -> FALSE | S18: Osteoarthritis | T18: Yes | U18: Critical | V18: Very Dissatisfied
A19: PID0018 | B19: O+ | C19: 167 | D19: =C19/100 -> 1.67 | E19: 93.5 | F19: =E19/(D19*D19) -> 33.525763 | G19: FALSE | H19: TRUE | I19: FALSE | J19: TRUE | K19: 128/70 | L19: 191 | M19: TRUE | N19: =IF(ISBLANK(M19),FALSE,IF(M19 ="Yes",TRUE,IF(M19="No",FALSE,M19))) -> TRUE | O19: FALSE | P19: =IF(ISBLANK(O19),FALSE,IF(O19 ="Yes",TRUE,IF(O19="No",FALSE,O19))) -> FALSE | Q19: TRUE | R19: =IF(ISBLANK(Q19),FALSE,IF(Q19 ="Yes",TRUE,IF(Q19="No",FALSE,Q19))) -> TRUE | S19: Childbirth | T19: No | U19: Critical | V19: Very Satisfied
A20: PID0019 | B20: O+ | C20: 171 | D20: =C20/100 -> 1.71 | E20: 99 | F20: =E20/(D20*D20) -> 33.856571 | G20: TRUE | H20: TRUE | I20: FALSE | J20: FALSE | K20: 117/76 | L20: 181 | M20: FALSE | N20: =IF(ISBLANK(M20),FALSE,IF(M20 ="Yes",TRUE,IF(M20="No",FALSE,M20))) -> FALSE | O20: TRUE | P20: =IF(ISBLANK(O20),FALSE,IF(O20 ="Yes",TRUE,IF(O20="No",FALSE,O20))) -> TRUE | Q20: TRUE | R20: =IF(ISBLANK(Q20),FALSE,IF(Q20 ="Yes",TRUE,IF(Q20="No",FALSE,Q20))) -> TRUE | S20: Allergic Reaction | T20: No | U20: Ongoing Treatment | V20: Dissatisfied
A21: PID0020 | B21: A- | C21: 161 | D21: =C21/100 -> 1.61 | E21: 73.7 | F21: =E21/(D21*D21) -> 28.432545 | G21: FALSE | H21: FALSE | I21: FALSE | J21: TRUE | K21: 121/77 | L21: 174 | M21: TRUE | N21: =IF(ISBLANK(M21),FALSE,IF(M21 ="Yes",TRUE,IF(M21="No",FALSE,M21))) -> TRUE | O21: TRUE | P21: =IF(ISBLANK(O21),FALSE,IF(O21 ="Yes",TRUE,IF(O21="No",FALSE,O21))) -> TRUE | Q21: TRUE | R21: =IF(ISBLANK(Q21),FALSE,IF(Q21 ="Yes",TRUE,IF(Q21="No",FALSE,Q21))) -> TRUE | S21: Respiratory Infection | T21: Yes | U21: Critical | V21: Satisfied
A22: PID0021 | B22: A- | C22: 161 | D22: =C22/100 -> 1.61 | E22: 54 | F22: =E22/(D22*D22) -> 20.83253 | G22: FALSE | H22: FALSE | I22: TRUE | J22: FALSE | K22: 114/72 | L22: 222 | N22: =IF(ISBLANK(M22),FALSE,IF(M22 ="Yes",TRUE,IF(M22="No",FALSE,M22))) -> FALSE | O22: FALSE | P22: =IF(ISBLANK(O22),FALSE,IF(O22 ="Yes",TRUE,IF(O22="No",FALSE,O22))) -> FALSE | Q22: FALSE | R22: =IF(ISBLANK(Q22),FALSE,IF(Q22 ="Yes",TRUE,IF(Q22="No",FALSE,Q22))) -> FALSE | S22: Kidney Stones | T22: No | U22: Ongoing Treatment | V22: Neutral
A23: PID0022 | B23: B- | C23: 172 | D23: =C23/100 -> 1.72 | E23: 76 | F23: =E23/(D23*D23) -> 25.689562 | G23: FALSE | H23: FALSE | I23: FALSE | J23: FALSE | K23: 112/84 | L23: 203 | M23: FALSE | N23: =IF(ISBLANK(M23),FALSE,IF(M23 ="Yes",TRUE,IF(M23="No",FALSE,M23))) -> FALSE | O23: FALSE | P23: =IF(ISBLANK(O23),FALSE,IF(O23 ="Yes",TRUE,IF(O23="No",FALSE,O23))) -> FALSE | Q23: FALSE | R23: =IF(ISBLANK(Q23),FALSE,IF(Q23 ="Yes",TRUE,IF(Q23="No",FALSE,Q23))) -> FALSE | S23: Fractured Leg | T23: Yes | U23: Ongoing Treatment | V23: Satisfied
A24: PID0023 | B24: A- | C24: 169 | D24: =C24/100 -> 1.69 | E24: 86.3 | F24: =E24/(D24*D24) -> 30.216029 | G24: FALSE | H24: FALSE | I24: FALSE | J24: FALSE | K24: 123/83 | L24: 157 | M24: FALSE | N24: =IF(ISBLANK(M24),FALSE,IF(M24 ="Yes",TRUE,IF(M24="No",FALSE,M24))) -> FALSE | O24: TRUE | P24: =IF(ISBLANK(O24),FALSE,IF(O24 ="Yes",TRUE,IF(O24="No",FALSE,O24))) -> TRUE | Q24: TRUE | R24: =IF(ISBLANK(Q24),FALSE,IF(Q24 ="Yes",TRUE,IF(Q24="No",FALSE,Q24))) -> TRUE | S24: Kidney Stones | T24: No | U24: Recovered | V24: Dissatisfied
A25: PID0024 | B25: O- | C25: 163 | D25: =C25/100 -> 1.63 | E25: 64.2 | F25: =E25/(D25*D25) -> 24.163499 | G25: FALSE | H25: FALSE | I25: FALSE | J25: FALSE | K25: 127/81 | L25: 216 | M25: FALSE | N25: =IF(ISBLANK(M25),FALSE,IF(M25 ="Yes",TRUE,IF(M25="No",FALSE,M25))) -> FALSE | O25: FALSE | P25: =IF(ISBLANK(O25),FALSE,IF(O25 ="Yes",TRUE,IF(O25="No",FALSE,O25))) -> FALSE | Q25: FALSE | R25: =IF(ISBLANK(Q25),FALSE,IF(Q25 ="Yes",TRUE,IF(Q25="No",FALSE,Q25))) -> FALSE | S25: Diabetes | T25: No | U25: Recovered | V25: Very Dissatisfied
A26: PID0025 | B26: B+ | C26: 175 | D26: =C26/100 -> 1.75 | E26: 61.5 | F26: =E26/(D26*D26) -> 20.081633 | G26: FALSE | H26: FALSE | I26: FALSE | J26: FALSE | K26: 128/71 | L26: 201 | M26: FALSE | N26: =IF(ISBLANK(M26),FALSE,IF(M26 ="Yes",TRUE,IF(M26="No",FALSE,M26))) -> FALSE | P26: =IF(ISBLANK(O26),FALSE,IF(O26 ="Yes",TRUE,IF(O26="No",FALSE,O26))) -> FALSE | Q26: FALSE | R26: =IF(ISBLANK(Q26),FALSE,IF(Q26 ="Yes",TRUE,IF(Q26="No",FALSE,Q26))) -> FALSE | S26: Osteoarthritis | T26: Yes | U26: Recovered | V26: Neutral
A27: PID0026 | B27: AB+ | C27: 150 | D27: =C27/100 -> 1.5 | E27: 68.4 | F27: =E27/(D27*D27) -> 30.4 | G27: FALSE | H27: TRUE | I27: FALSE | J27: TRUE | K27: 128/85 | L27: 170 | M27: TRUE | N27: =IF(ISBLANK(M27),FALSE,IF(M27 ="Yes",TRUE,IF(M27="No",FALSE,M27))) -> TRUE | O27: FALSE | P27: =IF(ISBLANK(O27),FALSE,IF(O27 ="Yes",TRUE,IF(O27="No",FALSE,O27))) -> FALSE | Q27: TRUE | R27: =IF(ISBLANK(Q27),FALSE,IF(Q27 ="Yes",TRUE,IF(Q27="No",FALSE,Q27))) -> TRUE | S27: Kidney Stones | T27: No | U27: Ongoing Treatment | V27: Dissatisfied
A28: PID0027 | B28: A+ | C28: 169 | D28: =C28/100 -> 1.69 | E28: 70.1 | F28: =E28/(D28*D28) -> 24.543959 | G28: FALSE | H28: TRUE | I28: FALSE | J28: FALSE | K28: 125/81 | L28: 213 | M28: FALSE | N28: =IF(ISBLANK(M28),FALSE,IF(M28 ="Yes",TRUE,IF(M28="No",FALSE,M28))) -> FALSE | O28: FALSE | P28: =IF(ISBLANK(O28),FALSE,IF(O28 ="Yes",TRUE,IF(O28="No",FALSE,O28))) -> FALSE | R28: =IF(ISBLANK(Q28),FALSE,IF(Q28 ="Yes",TRUE,IF(Q28="No",FALSE,Q28))) -> FALSE | S28: Osteoarthritis | T28: Yes | U28: Critical | V28: Very Dissatisfied
A29: PID0028 | B29: O- | C29: 163 | D29: =C29/100 -> 1.63 | E29: 54.5 | F29: =E29/(D29*D29) -> 20.512627 | G29: TRUE | H29: FALSE | I29: FALSE | J29: FALSE | K29: 125/79 | L29: 190 | M29: FALSE | N29: =IF(ISBLANK(M29),FALSE,IF(M29 ="Yes",TRUE,IF(M29="No",FALSE,M29))) -> FALSE | O29: FALSE | P29: =IF(ISBLANK(O29),FALSE,IF(O29 ="Yes",TRUE,IF(O29="No",FALSE,O29))) -> FALSE | Q29: FALSE | R29: =IF(ISBLANK(Q29),FALSE,IF(Q29 ="Yes",TRUE,IF(Q29="No",FALSE,Q29))) -> FALSE | S29: Cancer | T29: Yes | U29: Ongoing Treatment | V29: Very Dissatisfied
A30: PID0029 | B30: A- | C30: 166 | D30: =C30/100 -> 1.66 | E30: 95 | F30: =E30/(D30*D30) -> 34.47525 | G30: TRUE | H30: FALSE | I30: TRUE | J30: TRUE | K30: 114/70 | L30: 164 | M30: TRUE | N30: =IF(ISBLANK(M30),FALSE,IF(M30 ="Yes",TRUE,IF(M30="No",FALSE,M30))) -> TRUE | O30: FALSE | P30: =IF(ISBLANK(O30),FALSE,IF(O30 ="Yes",TRUE,IF(O30="No",FALSE,O30))) -> FALSE | Q30: TRUE | R30: =IF(ISBLANK(Q30),FALSE,IF(Q30 ="Yes",TRUE,IF(Q30="No",FALSE,Q30))) -> TRUE | S30: Prostate Cancer | T30: Yes | U30: Ongoing Treatment | V30: Very Dissatisfied
A31: PID0030 | B31: B- | C31: 166 | D31: =C31/100 -> 1.66 | E31: 73.9 | F31: =E31/(D31*D31) -> 26.818116 | G31: FALSE | H31: FALSE | I31: FALSE | J31: FALSE | K31: 117/75 | L31: 166 | M31: FALSE | N31: =IF(ISBLANK(M31),FALSE,IF(M31 ="Yes",TRUE,IF(M31="No",FALSE,M31))) -> FALSE | O31: FALSE | P31: =IF(ISBLANK(O31),FALSE,IF(O31 ="Yes",TRUE,IF(O31="No",FALSE,O31))) -> FALSE | Q31: FALSE | R31: =IF(ISBLANK(Q31),FALSE,IF(Q31 ="Yes",TRUE,IF(Q31="No",FALSE,Q31))) -> FALSE | S31: Allergic Reaction | T31: No | U31: Ongoing Treatment | V31: Neutral
A32: PID0031 | B32: A+ | C32: 161 | D32: =C32/100 -> 1.61 | E32: 59.4 | F32: =E32/(D32*D32) -> 22.915783 | G32: TRUE | H32: FALSE | I32: TRUE | J32: FALSE | K32: 127/71 | L32: 202 | M32: FALSE | N32: =IF(ISBLANK(M32),FALSE,IF(M32 ="Yes",TRUE,IF(M32="No",FALSE,M32))) -> FALSE | O32: FALSE | P32: =IF(ISBLANK(O32),FALSE,IF(O32 ="Yes",TRUE,IF(O32="No",FALSE,O32))) -> FALSE | Q32: FALSE | R32: =IF(ISBLANK(Q32),FALSE,IF(Q32 ="Yes",TRUE,IF(Q32="No",FALSE,Q32))) -> FALSE | S32: Cancer | T32: No | U32: Critical | V32: Neutral
A33: PID0032 | B33: A- | C33: 156 | D33: =C33/100 -> 1.56 | E33: 59.4 | F33: =E33/(D33*D33) -> 24.408284 | G33: FALSE | H33: TRUE | I33: TRUE | J33: FALSE | K33: 129/83 | L33: 196 | M33: FALSE | N33: =IF(ISBLANK(M33),FALSE,IF(M33 ="Yes",TRUE,IF(M33="No",FALSE,M33))) -> FALSE | O33: FALSE | P33: =IF(ISBLANK(O33),FALSE,IF(O33 ="Yes",TRUE,IF(O33="No",FALSE,O33))) -> FALSE | Q33: FALSE | R33: =IF(ISBLANK(Q33),FALSE,IF(Q33 ="Yes",TRUE,IF(Q33="No",FALSE,Q33))) -> FALSE | S33: Prostate Cancer | T33: No | U33: Ongoing Treatment | V33: Satisfied
A34: PID0033 | B34: A+ | C34: 170 | D34: =C34/100 -> 1.7 | E34: 73.7 | F34: =E34/(D34*D34) -> 25.50173 | G34: FALSE | H34: TRUE | I34: TRUE | J34: FALSE | K34: 126/73 | L34: 193 | M34: FALSE | N34: =IF(ISBLANK(M34),FALSE,IF(M34 ="Yes",TRUE,IF(M34="No",FALSE,M34))) -> FALSE | O34: FALSE | P34: =IF(ISBLANK(O34),FALSE,IF(O34 ="Yes",TRUE,IF(O34="No",FALSE,O34))) -> FALSE | Q34: FALSE | R34: =IF(ISBLANK(Q34),FALSE,IF(Q34 ="Yes",TRUE,IF(Q34="No",FALSE,Q34))) -> FALSE | S34: Stroke | T34: Yes | U34: Ongoing Treatment | V34: Neutral
A35: PID0034 | B35: A- | C35: 173 | D35: =C35/100 -> 1.73 | E35: 95.2 | F35: =E35/(D35*D35) -> 31.808614 | G35: FALSE | H35: FALSE | I35: FALSE | J35: TRUE | K35: 122/77 | L35: 156 | M35: TRUE | N35: =IF(ISBLANK(M35),FALSE,IF(M35 ="Yes",TRUE,IF(M35="No",FALSE,M35))) -> TRUE | O35: FALSE | P35: =IF(ISBLANK(O35),FALSE,IF(O35 ="Yes",TRUE,IF(O35="No",FALSE,O35))) -> FALSE | Q35: TRUE | R35: =IF(ISBLANK(Q35),FALSE,IF(Q35 ="Yes",TRUE,IF(Q35="No",FALSE,Q35))) -> TRUE | S35: Allergic Reaction | T35: No | U35: Recovered | V35: Neutral
A36: PID0035 | B36: O- | C36: 165 | D36: =C36/100 -> 1.65 | E36: 78.1 | F36: =E36/(D36*D36) -> 28.686869 | G36: FALSE | H36: FALSE | I36: FALSE | J36: FALSE | K36: 121/70 | L36: 191 | M36: FALSE | N36: =IF(ISBLANK(M36),FALSE,IF(M36 ="Yes",TRUE,IF(M36="No",FALSE,M36))) -> FALSE | O36: TRUE | P36: =IF(ISBLANK(O36),FALSE,IF(O36 ="Yes",TRUE,IF(O36="No",FALSE,O36))) -> TRUE | Q36: TRUE | R36: =IF(ISBLANK(Q36),FALSE,IF(Q36 ="Yes",TRUE,IF(Q36="No",FALSE,Q36))) -> TRUE | S36: Cancer | T36: Yes | U36: Critical | V36: Neutral
A37: PID0036 | B37: B+ | C37: 161 | D37: =C37/100 -> 1.61 | E37: 78.2 | F37: =E37/(D37*D37) -> 30.168589 | G37: FALSE | H37: FALSE | I37: FALSE | J37: FALSE | K37: 126/79 | L37: 191 | N37: =IF(ISBLANK(M37),FALSE,IF(M37 ="Yes",TRUE,IF(M37="No",FALSE,M37))) -> FALSE | O37: TRUE | P37: =IF(ISBLANK(O37),FALSE,IF(O37 ="Yes",TRUE,IF(O37="No",FALSE,O37))) -> TRUE | Q37: TRUE | R37: =IF(ISBLANK(Q37),FALSE,IF(Q37 ="Yes",TRUE,IF(Q37="No",FALSE,Q37))) -> TRUE | S37: Cancer | T37: No | U37: Recovered | V37: Dissatisfied
A38: PID0037 | B38: O+ | C38: 156 | D38: =C38/100 -> 1.56 | E38: 60.6 | F38: =E38/(D38*D38) -> 24.901381 | G38: FALSE | H38: TRUE | I38: TRUE | J38: FALSE | K38: 115/82 | L38: 161 | M38: FALSE | N38: =IF(ISBLANK(M38),FALSE,IF(M38 ="Yes",TRUE,IF(M38="No",FALSE,M38))) -> FALSE | O38: FALSE | P38: =IF(ISBLANK(O38),FALSE,IF(O38 ="Yes",TRUE,IF(O38="No",FALSE,O38))) -> FALSE | Q38: FALSE | R38: =IF(ISBLANK(Q38),FALSE,IF(Q38 ="Yes",TRUE,IF(Q38="No",FALSE,Q38))) -> FALSE | S38: Appendicitis | T38: No | U38: Recovered | V38: Satisfied
A39: PID0038 | B39: O+ | C39: 169 | D39: =C39/100 -> 1.69 | E39: 99.2 | F39: =E39/(D39*D39) -> 34.732677 | G39: TRUE | H39: FALSE | I39: FALSE | J39: TRUE | K39: 121/79 | L39: 160 | M39: TRUE | N39: =IF(ISBLANK(M39),FALSE,IF(M39 ="Yes",TRUE,IF(M39="No",FALSE,M39))) -> TRUE | O39: TRUE | P39: =IF(ISBLANK(O39),FALSE,IF(O39 ="Yes",TRUE,IF(O39="No",FALSE,O39))) -> TRUE | Q39: TRUE | R39: =IF(ISBLANK(Q39),FALSE,IF(Q39 ="Yes",TRUE,IF(Q39="No",FALSE,Q39))) -> TRUE | S39: Allergic Reaction | T39: Yes | U39: Critical | V39: Very Satisfied
A40: PID0039 | B40: O+ | C40: 159 | D40: =C40/100 -> 1.59 | E40: 58.9 | F40: =E40/(D40*D40) -> 23.298129 | G40: FALSE | H40: TRUE | I40: FALSE | J40: FALSE | K40: 125/74 | L40: 212 | M40: FALSE | N40: =IF(ISBLANK(M40),FALSE,IF(M40 ="Yes",TRUE,IF(M40="No",FALSE,M40))) -> FALSE | O40: FALSE | P40: =IF(ISBLANK(O40),FALSE,IF(O40 ="Yes",TRUE,IF(O40="No",FALSE,O40))) -> FALSE | Q40: FALSE | R40: =IF(ISBLANK(Q40),FALSE,IF(Q40 ="Yes",TRUE,IF(Q40="No",FALSE,Q40))) -> FALSE | S40: Cancer | T40: Yes | U40: Critical | V40: Satisfied
...

Sheet Patient Education
A1: Patient Id | B1: Education Level | C1: Occupation | D1: Company Type
A2: PID0001 | B2: Master's Degree | C2: Manager | D2: Startup
A3: PID0002 | B3: Bachelor's Degree | C3: Teacher | D3: Startup
A4: PID0003 | B4: School | C4: Clerical Staff | D4: public
A5: PID0004 | B5: School | C5: Retail Worker | D5: Public
A6: PID0005 | B6: Post-graduate | C6: Professor | D6: Startup
A7: PID0006 | B7: PhD | C7: Scientist | D7: Private
A8: PID0007 | B8: Uneducated | C8: Unemployed | D8: None
A9: PID0008 | B9: Uneducated | C9: Labourer | D9: None
A10: PID0009 | B10: School | C10: Driver | D10: Public
A11: PID0010 | B11: Master's Degree | C11: Doctor | D11: Startup
A12: PID0011 | B12: Master's Degree | C12: Doctor | D12: Public
... A1001: PID1000 | B1001: Bachelor's Degree | C1001: Teacher | D1001: Startup

Sheet Billing Details
A1: Patient Id | B1: Procedure | C1: A | D1: B | E1: C | F1: Cost Per Visit | G1: Number of Visits | H1: region | I1: Total Bill | K1: central tendecny MEAN | L1: cverage | M1: median | N1: mode | O1: Room Number | P1: Admission Date | Q1: Discharge Date | R1: Insurance Provider | S1: Covered by Insurance | T1: Sum Covered by Insurance
A2: PID0001 | B2: Delivery and Postnatal Care | C2: {=_xlfn.UNIQUE(B2:B1001)} -> Delivery and Postnatal Care | D2: South | E2: =SUMIFS('Billing Details'!T:T,'Billing Details'!D:D,'Billing Details'!$J$2,'Billing Details'!B:B,'Billing Details'!C2) * 100/ SUMIFS(I:I,'Billing Details'!D:D,'Billing Details'!$J$2,'Billing Details'!B:B,'Billing Details'!C2) -> 56.192083 | F2: 12000 | G2: 5 | H2: South | I2: =F2*G2 -> 60000 | J2: South | K2: =AVERAGEIF('Patient Demographics'!K2:K1001,'Patient Demographics'!O2,'Billing Details'!I2:I1001) -> 47541.873 | L2: =SUMIF(H2:H1001,J2,T2:T1001)*100/SUMIF(H2:H1001,J2,I2:I1001) -> 54.667953 | M2: {=MEDIAN(IF(H2:H1001="South",I2:I1001))} -> 21000 | O2: 212 | P2: 44905 | Q2: 44908 | R2: Blue Cross | S2: TRUE | T2: 32168.65
A3: PID0002 | B3: X-Ray and Splint | C3: X-Ray and Splint | D3: West | E3: =SUMIFS('Billing Details'!T:T,'Billing Details'!D:D,'Billing Details'!$J$2,'Billing Details'!B:B,'Billing Details'!C3) * 100/ SUMIFS(I:I,'Billing Details'!D:D,'Billing Details'!$J$2,'Billing Details'!B:B,'Billing Details'!C3) -> 49.730645 | F3: 500 | G3: 1 | H3: West | I3: =F3*G3 -> 500 | J3: West | K3: =AVERAGEIF('Patient Demographics'!K3:K1002,'Patient Demographics'!O3,'Billing Details'!I3:I1001) -> 62654.618 | L3: =SUMIF(H3:H1002,J3,T3:T1002)*100/SUMIF(H3:H1002,J3,I3:I1002) -> 54.139675 | M3: {=MEDIAN(IF(H3:H1001="North",I3:I1001))} -> 22500 | O3: 173 | P3: 43992 | Q3: 43995 | S3: FALSE
A4: PID0003 | B4: Lithotripsy | C4: Lithotripsy | D4: North | E4: =SUMIFS('Billing Details'!T:T,'Billing Details'!D:D,'Billing Details'!$J$2,'Billing Details'!B:B,'Billing Details'!C4) * 100/ SUMIFS(I:I,'Billing Details'!D:D,'Billing Details'!$J$2,'Billing Details'!B:B,'Billing Details'!C4) -> 52.582664 | F4: 6000 | G4: 3 | H4: North | I4: =F4*G4 -> 18000 | J4: North | K4: =AVERAGEIF('Patient Demographics'!K4:K1003,'Patient Demographics'!O4,'Billing Details'!I4:I1002) -> 54700.794 | L4: =SUMIF(H4:H1003,J4,T4:T1003)*100/SUMIF(H4:H1003,J4,I4:I1003) -> 55.759287 | M4: {=MEDIAN(IF(H4:H1002="East",I4:I1002))} -> 22500 | O4: 216 | P4: 45006 | Q4: 45009 | R4: Blue Cross | S4: TRUE | T4: 12004.65
A5: PID0004 | B5: Delivery and Postnatal Care | C5: Cast and Physical Therapy | D5: South | E5: =SUMIFS('Billing Details'!T:T,'Billing Details'!D:D,'Billing Details'!$J$2,'Billing Details'!B:B,'Billing Details'!C5) * 100/ SUMIFS(I:I,'Billing Details'!D:D,'Billing Details'!$J$2,'Billing Details'!B:B,'Billing Details'!C5) -> 49.623381 | F5: 12000 | G5: 4 | H5: South | I5: =F5*G5 -> 48000 | J5: East | K5: =AVERAGEIF('Patient Demographics'!K5:K1004,'Patient Demographics'!O5,'Billing Details'!I5:I1003) -> 61180.882 | L5: =SUMIF(H5:H1004,J5,T5:T1004)*100/SUMIF(H5:H1004,J5,I5:I1004) -> 55.831487 | M5: {=MEDIAN(IF(H5:H1003="West",I5:I1003))} -> 31000 | O5: 125 | P5: 44506 | Q5: 44512 | R5: Aetna | S5: TRUE | T5: 32956.92
